Epoch 1
-------------------------------
Traceback (most recent call last):
  File "/Users/mukh/opt/anaconda3/lib/python3.9/site-packages/pandas/core/indexes/base.py", line 3629, in get_loc
    return self._engine.get_loc(casted_key)
  File "pandas/_libs/index.pyx", line 136, in pandas._libs.index.IndexEngine.get_loc
  File "pandas/_libs/index.pyx", line 163, in pandas._libs.index.IndexEngine.get_loc
  File "pandas/_libs/hashtable_class_helper.pxi", line 5198, in pandas._libs.hashtable.PyObjectHashTable.get_item
  File "pandas/_libs/hashtable_class_helper.pxi", line 5206, in pandas._libs.hashtable.PyObjectHashTable.get_item
KeyError: 'Intelligibility_Label_id'
The above exception was the direct cause of the following exception:
Traceback (most recent call last):
  File "/Users/mukh/Desktop/Work/Dysarthria/Dysarthria_severity_pred/main.py", line 208, in <module>
    main()
  File "/Users/mukh/Desktop/Work/Dysarthria/Dysarthria_severity_pred/main.py", line 148, in main
    train_model(args, model, train_dataloader, val_dataloader, optimizer, loss_fn, device, output_path = output_path, wandb=wandb)
  File "/Users/mukh/Desktop/Work/Dysarthria/Dysarthria_severity_pred/src/train/train.py", line 84, in train_model
    train_loss = train_loop(train_loader, model, loss_fn, optimizer, device, wandb)
  File "/Users/mukh/Desktop/Work/Dysarthria/Dysarthria_severity_pred/src/train/train.py", line 13, in train_loop
    for batch, (batch_input, batch_labels) in enumerate(dataloader):
  File "/Users/mukh/opt/anaconda3/lib/python3.9/site-packages/torch/utils/data/dataloader.py", line 633, in __next__
    data = self._next_data()
  File "/Users/mukh/opt/anaconda3/lib/python3.9/site-packages/torch/utils/data/dataloader.py", line 677, in _next_data
    data = self._dataset_fetcher.fetch(index)  # may raise StopIteration
  File "/Users/mukh/opt/anaconda3/lib/python3.9/site-packages/torch/utils/data/_utils/fetch.py", line 51, in fetch
    data = [self.dataset[idx] for idx in possibly_batched_index]
  File "/Users/mukh/opt/anaconda3/lib/python3.9/site-packages/torch/utils/data/_utils/fetch.py", line 51, in <listcomp>
    data = [self.dataset[idx] for idx in possibly_batched_index]
  File "/Users/mukh/Desktop/Work/Dysarthria/Dysarthria_severity_pred/src/data/make_dataset.py", line 36, in __getitem__
    label = self.metadata.loc[self.metadata.index[idx], "Intelligibility_Label_id"]
  File "/Users/mukh/opt/anaconda3/lib/python3.9/site-packages/pandas/core/indexing.py", line 960, in __getitem__
    return self.obj._get_value(*key, takeable=self._takeable)
  File "/Users/mukh/opt/anaconda3/lib/python3.9/site-packages/pandas/core/frame.py", line 3615, in _get_value
    series = self._get_item_cache(col)
  File "/Users/mukh/opt/anaconda3/lib/python3.9/site-packages/pandas/core/frame.py", line 3931, in _get_item_cache
    loc = self.columns.get_loc(item)
  File "/Users/mukh/opt/anaconda3/lib/python3.9/site-packages/pandas/core/indexes/base.py", line 3631, in get_loc
    raise KeyError(key) from err
KeyError: 'Intelligibility_Label_id'